<?xml version="1.0" ?>
<!-- =================================================================================== -->
<!-- |    This document was autogenerated by xacro from /opt/ros/kinetic/share/moveit_resources/panda_description/urdf/panda.urdf | -->
<!-- |    EDITING THIS FILE BY HAND IS NOT RECOMMENDED                                 | -->
<!-- =================================================================================== -->
<robot name="panda" xmlns:xacro="http://www.ros.org/wiki/xacro">
    <link name="dummy"></link>
    <joint name="dummy_joint" type="fixed">
     <parent link="dummy"/>
     <child link="panda_link0"/>
   </joint>
    <link name="panda_link0">
        <visual>
            <geometry>
                <mesh filename="package://moveit_resources_panda_description/meshes/visual/link0.dae" />
            </geometry>
        </visual>
        <collision>
            <geometry>
                <mesh filename="package://moveit_resources_panda_description/meshes/collision/link0.stl" />
            </geometry>
        </collision>
        <inertial>
            <mass value="2.92"/>
            <origin rpy="0 0 0" xyz="-0.025566 -2.88e-05 0.057332"/>
            <inertia ixx="0.00782229414331" ixy="-1.56191622996e-05" ixz="-0.00126005738123" iyy="0.0109027971813" iyz="1.08233858202e-05" izz="0.0102355503949"/>
        </inertial>
    </link>
    <link name="panda_link1">
        <visual>
            <geometry>
                <mesh filename="package://moveit_resources_panda_description/meshes/visual/link1.dae" />
            </geometry>
        </visual>
        <collision>
            <geometry>
                <mesh filename="package://moveit_resources_panda_description/meshes/collision/link1.stl" />
            </geometry>
        </collision>
        <inertial>
            <mass value="2.74"/>
            <origin rpy="0 0 0" xyz="0 -0.0324958 -0.0675818"/>
            <inertia ixx="0.0180416958283" ixy="0.0" ixz="0.0" iyy="0.0159136071891" iyz="0.0046758424612" izz="0.00620690827127"/>
        </inertial>        
    </link>
    <joint name="panda_joint1" type="revolute">
        <safety_controller k_position="100.0" k_velocity="40.0" soft_lower_limit="-2.8973" soft_upper_limit="2.8973" />
        <origin rpy="0 0 0" xyz="0 0 0.333" />
        <parent link="panda_link0" />
        <child link="panda_link1" />
        <axis xyz="0 0 1" />
        <limit effort="87" lower="-2.9671" upper="2.9671" velocity="2.3925" />
    </joint>
    <link name="panda_link2">
        <visual>
            <geometry>
                <mesh filename="package://moveit_resources_panda_description/meshes/visual/link2.dae" />
            </geometry>
        </visual>
        <collision>
            <geometry>
                <mesh filename="package://moveit_resources_panda_description/meshes/collision/link2.stl" />
            </geometry>
        </collision>
        <inertial>
            <mass value="2.74"/>
            <origin rpy="0 0 0" xyz="0 -0.06861 0.0322285"/>
            <inertia ixx="0.0182856182281" ixy="0.0" ixz="0.0" iyy="0.00621358421175" iyz="-0.00472844221905" izz="0.0161514346309"/>
        </inertial>        
    </link>
    <joint name="panda_joint2" type="revolute">
        <safety_controller k_position="100.0" k_velocity="40.0" soft_lower_limit="-1.7628" soft_upper_limit="1.7628" />
        <origin rpy="-1.57079632679 0 0" xyz="0 0 0" />
        <parent link="panda_link1" />
        <child link="panda_link2" />
        <axis xyz="0 0 1" />
        <limit effort="87" lower="-1.8326" upper="1.8326" velocity="2.3925" />
    </joint>
    <link name="panda_link3">
        <visual>
            <geometry>
                <mesh filename="package://moveit_resources_panda_description/meshes/visual/link3.dae" />
            </geometry>
        </visual>
        <collision>
            <geometry>
                <mesh filename="package://moveit_resources_panda_description/meshes/collision/link3.stl" />
            </geometry>
        </collision>
        <inertial>
            <mass value="2.38"/>
            <origin rpy="0 0 0" xyz="0.0469893 0.0316374 -0.031704"/>
            <inertia ixx="0.00771376630908" ixy="-0.00248490625138" ixz="-0.00332147581033" iyy="0.00989108008727" iyz="-0.00217796151484" izz="0.00811723558464"/>
        </inertial>
    </link>
    <joint name="panda_joint3" type="revolute">
        <safety_controller k_position="100.0" k_velocity="40.0" soft_lower_limit="-2.8973" soft_upper_limit="2.8973" />
        <origin rpy="1.57079632679 0 0" xyz="0 -0.316 0" />
        <parent link="panda_link2" />
        <child link="panda_link3" />
        <axis xyz="0 0 1" />
        <limit effort="87" lower="-2.9671" upper="2.9671" velocity="2.3925" />
    </joint>
    <link name="panda_link4">
        <inertial>
            <mass value="2.38"/>
            <origin rpy="0 0 0" xyz="-0.0360446 0.0336853 0.031882"/>
            <inertia ixx="0.00799663881132" ixy="0.00347095570217" ixz="-0.00241222942995" iyy="0.00825390705278" iyz="0.00235774044121" izz="0.0102515004345"/>
        </inertial>    
        <visual>
            <geometry>
                <mesh filename="package://moveit_resources_panda_description/meshes/visual/link4.dae" />
            </geometry>
        </visual>
        <collision>
            <geometry>
                <mesh filename="package://moveit_resources_panda_description/meshes/collision/link4.stl" />
            </geometry>
        </collision>
    </link>
    <joint name="panda_joint4" type="revolute">
        <safety_controller k_position="100.0" k_velocity="40.0" soft_lower_limit="-3.0718" soft_upper_limit="0.0175" />
        <origin rpy="1.57079632679 0 0" xyz="0.0825 0 0" />
        <parent link="panda_link3" />
        <child link="panda_link4" />
        <axis xyz="0 0 1" />
        <limit effort="87" lower="-3.1416" upper="0.0873" velocity="2.3925" />
    </joint>
    <link name="panda_link5">
        <inertial>
            <mass value="2.74"/>
            <origin rpy="0 0 0" xyz="0 0.0610427 -0.104176"/>
            <inertia ixx="0.030371374513" ixy="6.50283587108e-07" ixz="-1.05129179916e-05" iyy="0.0288752887402" iyz="-0.00775653445787" izz="0.00444134056164"/>
        </inertial>    
        <visual>
            <geometry>
                <mesh filename="package://moveit_resources_panda_description/meshes/visual/link5.dae" />
            </geometry>
        </visual>
        <collision>
            <geometry>
                <mesh filename="package://moveit_resources_panda_description/meshes/collision/link5.stl" />
            </geometry>
        </collision>
    </link>
    <joint name="panda_joint5" type="revolute">
        <safety_controller k_position="100.0" k_velocity="40.0" soft_lower_limit="-3.13" soft_upper_limit="3.13" />
        <origin rpy="-1.57079632679 0 0" xyz="-0.0825 0.384 0" />
        <parent link="panda_link4" />
        <child link="panda_link5" />
        <axis xyz="0 0 1" />
        <limit effort="12" lower="-3.13" upper="3.13" velocity="2.8710" />
    </joint>
    <link name="panda_link6">
        <inertial>
            <mass value="1.55"/>
            <origin rpy="0 0 0" xyz="0.0510509 0.009108 0.0106343"/>
            <inertia ixx="0.00303336450376" ixy="-0.000437276865508" ixz="0.000629257294877" iyy="0.00404479911567" iyz="0.000130472021025" izz="0.00558234286039"/>
        </inertial>
        <visual>
            <geometry>
                <mesh filename="package://moveit_resources_panda_description/meshes/visual/link6.dae" />
            </geometry>
        </visual>
        <collision>
            <geometry>
                <mesh filename="package://moveit_resources_panda_description/meshes/collision/link6.stl" />
            </geometry>
        </collision>
    </link>
    <joint name="panda_joint6" type="revolute">
        <safety_controller k_position="100.0" k_velocity="40.0" soft_lower_limit="-0.0175" soft_upper_limit="3.7525" />
        <origin rpy="1.57079632679 0 0" xyz="0 0 0" />
        <parent link="panda_link5" />
        <child link="panda_link6" />
        <axis xyz="0 0 1" />
        <limit effort="12" lower="-0.0873" upper="3.8223" velocity="2.8710" />
    </joint>
    <link name="panda_link7">
        <inertial>
            <mass value="0.54"/>
            <origin rpy="0 0 0" xyz="0.0109695 0.0107965 0.0650411"/>
            <inertia ixx="0.000888868887021" ixy="-0.00012239074652" ixz="3.98699829666e-05" iyy="0.000888001373233" iyz="-9.33825115206e-05" izz="0.0007176834609"/>
        </inertial>    
        <visual>
            <geometry>
                <mesh filename="package://moveit_resources_panda_description/meshes/visual/link7.dae" />
            </geometry>
        </visual>
        <collision>
            <geometry>
                <mesh filename="package://moveit_resources_panda_description/meshes/collision/link7.stl" />
            </geometry>
        </collision>
    </link>

    <joint name="panda_joint7" type="fixed">
        <origin rpy="1.57079632679 0 0" xyz="0.088 0 0"/>
        <parent link="panda_link6" />
        <child link="panda_link7" />
    </joint>

    <link name="tip_link"></link>

    <joint name="tip_joint" type="fixed">
        <origin xyz="0 0 0.103" rpy="0 -1.57079632679 0"/>
        <parent link="panda_link7" />
        <child link="tip_link" />
    </joint>

    <link name="ee_base_link"></link>
    
    <joint name="ee_base_link_joint" type="fixed">
        <origin xyz="0 0 0" rpy="0 0 0"/>
        <parent link="tip_link" />
        <child link="ee_base_link" />
    </joint>

    <!-- End Effector Link -->
    <link name="end_effector_link">
    <visual>
      <origin xyz="0 0 0.0" rpy="0 0 0"/>
      <geometry>
        <mesh filename="package://moveit_resources_panda_description/meshes/visual/fixed_spatula.dae"/>
      </geometry>
    </visual>
    <collision>
      <origin xyz="0 0 0.0" rpy="0 0 0"/>
      <geometry>
        <mesh filename="package://moveit_resources_panda_description/meshes/collision/fixed_spatula.dae"/>
      </geometry>
    </collision>
    <inertial>
      <mass value="0.5"/>
      <origin xyz="0 0 0" rpy="0 0 0"/>
      <inertia ixx="0.00125" ixy="0.0" ixz="0.0" iyy="0.00125" iyz="0.0" izz="0.0025"/>
    </inertial>
  </link>

  <!-- Sliding Link -->
  <link name="sliding_link">
    <visual>
      <origin xyz="0 0 0" rpy="0 0 0"/>
      <geometry>
        <mesh filename="package://moveit_resources_panda_description/meshes/visual/slide_spatula.dae"/>
      </geometry>
    </visual>
    <collision>
      <origin xyz="0 0 0" rpy="0 0 0"/>
      <geometry>
        <mesh filename="package://moveit_resources_panda_description/meshes/collision/slide_spatula.dae"/>
      </geometry>
    </collision>
    <inertial>
      <mass value="0.05"/>
      <origin xyz="0 0 0" rpy="0 0 0"/>
      <inertia ixx="0.0001" ixy="0.0" ixz="0.0" iyy="0.0001" iyz="0.0" izz="0.0002"/>
    </inertial>
  </link>

  <!-- Revolute Joint: Robot to End Effector -->
  <joint name="ee_connector_joint" type="revolute">
    <parent link="ee_base_link"/>
    <child link="end_effector_link"/>
    <origin rpy="0 0 0" xyz="0 0 0"/>
    <limit effort="12" lower="-3.1414" upper="3.1415"  velocity="2.6100"/>
  </joint>

  <!-- Prismatic Joint: End Effector to Sliding Link -->
  <joint name="slider_joint" type="prismatic">
    <parent link="end_effector_link"/>
    <child link="sliding_link"/>
    <origin xyz="0.14 0.06 -0.003" rpy="0 0 0"/>
    <axis xyz="1 0 0"/>
    <limit lower="0" upper="0.1" effort="20.0" velocity="0.5"/>
  </joint>

</robot>
